File: example_data/e16014_07_t2t_001.ras
* random comment for jakub
*RAS_DATA_START
*RAS_HEADER_START
*DISP_FMT_X "%.2f"
*DISP_FMT_Y "%.0f"
*DISP_FULLSCALE "9013208.2219199985"
*DISP_LINE_COLOR "255.0000000000"
*DISP_LINE_STYLE "0.0000000000"
*DISP_LINE_WIDTH "0.2500000000"
*DISP_NOTE "Collected Data-5"
*DISP_OFFSET_Y "0.0000000000"
*DISP_PEAKSEARCH_UNIT_Y "cps"
*DISP_RANGE_BOTTOM "0.0100000000"
*DISP_RANGE_LEFT "21.0006000000"
*DISP_RANGE_LOGCUTOFF "0.0100000000"
*DISP_RANGE_RIGHT "24.0002000000"
*DISP_RANGE_TOP "9013208.2219199985"
*DISP_SCALE_MODE_Y "2.0000000000"
*DISP_TAB_NAME "2-Theta/Omega"
*DISP_TITLE_Y "Intensity"
*DISP_UNIT_Y "cps"
*DISP_WINDOW_NAME "MSG_MANCTRL"
*FILE_COMMENT " "
*FILE_MD5 ""
*FILE_MEMO " "
*FILE_OPERATOR "Administrator"
*FILE_SAMPLE "e16014"
*FILE_TYPE "RAS_RAW"
*FILE_USERGROUP "System Manager"
*FILE_VERSION "1.0000000000"
*HW_ATTACHMENT_ID "ATT0021"
*HW_ATTACHMENT_NAME "XY-20mm|XY-20mm"
*HW_COUNTER_ID-0 "CUT0021"
*HW_COUNTER_ID-1 "CUT0020"
*HW_COUNTER_ID-2 "CUT0020"
*HW_COUNTER_ID-3 "CSL0021"
*HW_COUNTER_ID-4 "CMC0021"
*HW_COUNTER_NAME-0 "SC-70|SC-70"
*HW_COUNTER_NAME-1 "None|None"
*HW_COUNTER_NAME-2 "None|None"
*HW_COUNTER_NAME-3 "BBM|BBM"
*HW_COUNTER_NAME-4 "���o�탂�m�N�����[�^|Detector monochromator"
*HW_COUNTER_SELECT_NAME "SC-70|SC-70"
*HW_ECP_HV "640.5000000000"
*HW_ECP_HV_UNIT "V"
*HW_GONIOMETER_ID "GON0023"
*HW_GONIOMETER_NAME "SmartLab|SmartLab"
*HW_GONIOMETER_RADIUS-0 "90.0"
*HW_GONIOMETER_RADIUS-1 "114.0"
*HW_GONIOMETER_RADIUS-2 "190.0"
*HW_GONIOMETER_RADIUS-3 "300.0"
*HW_GONIOMETER_RADIUS-4 "187.0"
*HW_GONIOMETER_RADIUS-5 "300.0"
*HW_GONIOMETER_RADIUS-6 "113.0"
*HW_GONIOMETER_RADIUS-7 "331.0"
*HW_I_OPT_ID-0 "CBO0021"
*HW_I_OPT_ID-1 "ICR0021"
*HW_I_OPT_ID-2 "ISL0021"
*HW_I_OPT_ID-3 "ISO0021"
*HW_I_OPT_ID-4 "IAD0021"
*HW_I_OPT_ID-5 "IPR0001"
*HW_I_OPT_NAME-0 "CBO���j�b�g|CBO unit"
*HW_I_OPT_NAME-1 "�W�����ˌ��w���j�b�g|Standard incident optical unit"
*HW_I_OPT_NAME-2 "�W�����˃X���b�g�{�b�N�X|Standard incident slit box"
*HW_I_OPT_NAME-3 "���˕��s�X���b�g|Incident parallel slit"
*HW_I_OPT_NAME-4 "���萧���X���b�g|Length limiting slit"
*HW_I_OPT_NAME-5 "None|None"
*HW_R_ATTENUATER_AUTOMODE "1"
*HW_R_OPT_ID-0 "RSS0021"
*HW_R_OPT_ID-1 "RCR0022"
*HW_R_OPT_ID-2 "RSO0021"
*HW_R_OPT_ID-3 "RRS0021"
*HW_R_OPT_ID-4 "ATN0021"
*HW_R_OPT_ID-5 "RFL0021"
*HW_R_OPT_ID-6 "RAD0021"
*HW_R_OPT_NAME-0 "�W�������X���b�g�{�b�N�X1|Standard receiving slit box * 1"
*HW_R_OPT_NAME-1 "�W���������w���j�b�g1|Standard receiving unit * 1"
*HW_R_OPT_NAME-2 "�W���������w���j�b�g2|Standard receiving optical unit * 2"
*HW_R_OPT_NAME-3 "�W�������X���b�g�{�b�N�X2|Standard receiving slit box * 2"
*HW_R_OPT_NAME-4 "�W���A�b�e�l�[�^|Standard Attenuator"
*HW_R_OPT_NAME-5 "Cu K��|Cu K-beta"
*HW_R_OPT_NAME-6 "�����p�����X���b�g|Alignment receiving slit"
*HW_SAMPLE_HOLDER_ID "SMP0021"
*HW_SAMPLE_HOLDER_NAME "�ԃ�Z�N���[�h��|Chi phi Z cradle"
*HW_XG_CURRENT_MAX "200"
*HW_XG_CURRENT_MIN "10"
*HW_XG_CURRENT_RESOLUTION "2"
*HW_XG_CURRENT_UNIT "mA"
*HW_XG_FOCUS ""
*HW_XG_FOCUS_TYPE "Normal"
*HW_XG_ID ""
*HW_XG_NAME "9kW �J����(45kV 200mA ID:1700)|9kW Rotating anode(45kV 200mA ID:1700)"
*HW_XG_TARGET_ATOMIC_NUMBER "29.0000000000"
*HW_XG_TARGET_NAME "Cu"
*HW_XG_TYPE "Rota"
*HW_XG_VOLTAGE_MAX "45"
*HW_XG_VOLTAGE_MIN "20"
*HW_XG_VOLTAGE_RESOLUTION "2"
*HW_XG_VOLTAGE_UNIT "kV"
*HW_XG_WATT_MAX "9"
*HW_XG_WATT_UNIT "kW"
*HW_XG_WAVE_LENGTH_ALPHA1 "1.540593"
*HW_XG_WAVE_LENGTH_ALPHA2 "1.544414"
*HW_XG_WAVE_LENGTH_BETA "1.392250"
*MEAS_COND_AXIS_NAME-0 "Theta/2-Theta"
*MEAS_COND_AXIS_NAME-1 "2-Theta"
*MEAS_COND_AXIS_NAME-2 "Omega"
*MEAS_COND_AXIS_NAME-3 "Chi"
*MEAS_COND_AXIS_NAME-4 "Phi"
*MEAS_COND_AXIS_NAME-5 "Z"
*MEAS_COND_AXIS_NAME-6 "X"
*MEAS_COND_AXIS_NAME-7 "Y"
*MEAS_COND_AXIS_NAME-8 "2-Theta/Omega"
*MEAS_COND_AXIS_NAME-9 "Theta_s"
*MEAS_COND_AXIS_NAME-10 "Theta_d"
*MEAS_COND_AXIS_NAME-11 "Ts"
*MEAS_COND_AXIS_NAME-12 "CBO selection slit"
*MEAS_COND_AXIS_NAME-13 "M"
*MEAS_COND_AXIS_NAME-14 "Incident parallel slit"
*MEAS_COND_AXIS_NAME-15 "Incident slit"
*MEAS_COND_AXIS_NAME-16 ""
*MEAS_COND_AXIS_NAME-17 "Zs"
*MEAS_COND_AXIS_NAME-18 "Incident optical device"
*MEAS_COND_AXIS_NAME-19 "Omega_m"
*MEAS_COND_AXIS_NAME-20 "Length limiting slit"
*MEAS_COND_AXIS_NAME-21 "Center slit"
*MEAS_COND_AXIS_NAME-22 "Filter"
*MEAS_COND_AXIS_NAME-23 "Receiving slit * 1"
*MEAS_COND_AXIS_NAME-24 "Receiving slit * 2"
*MEAS_COND_AXIS_NAME-25 "Receiving optical device"
*MEAS_COND_AXIS_NAME-26 "Receiving parallel slit"
*MEAS_COND_AXIS_NAME-27 "Alignment receiving slit"
*MEAS_COND_AXIS_NAME-28 ""
*MEAS_COND_AXIS_NAME-29 ""
*MEAS_COND_AXIS_NAME-30 "Zd"
*MEAS_COND_AXIS_NAME-31 "Attenuator"
*MEAS_COND_AXIS_NAME-32 "Diffracted beam monochromator"
*MEAS_COND_AXIS_NAME-33 "Monochromator slit"
*MEAS_COND_AXIS_NAME-34 ""
*MEAS_COND_AXIS_NAME-35 ""
*MEAS_COND_AXIS_NAME-36 "Primary beam"
*MEAS_COND_AXIS_NAME-37 "HV"
*MEAS_COND_AXIS_NAME-38 "PHA"
*MEAS_COND_AXIS_NAME_INTERNAL-0 "TwoThetaTheta"
*MEAS_COND_AXIS_NAME_INTERNAL-1 "TwoTheta"
*MEAS_COND_AXIS_NAME_INTERNAL-2 "Omega"
*MEAS_COND_AXIS_NAME_INTERNAL-3 "Chi"
*MEAS_COND_AXIS_NAME_INTERNAL-4 "Phi"
*MEAS_COND_AXIS_NAME_INTERNAL-5 "Z"
*MEAS_COND_AXIS_NAME_INTERNAL-6 "X"
*MEAS_COND_AXIS_NAME_INTERNAL-7 "Y"
*MEAS_COND_AXIS_NAME_INTERNAL-8 "TwoThetaOmega"
*MEAS_COND_AXIS_NAME_INTERNAL-9 "ThetaS"
*MEAS_COND_AXIS_NAME_INTERNAL-10 "ThetaD"
*MEAS_COND_AXIS_NAME_INTERNAL-11 "Ts"
*MEAS_COND_AXIS_NAME_INTERNAL-12 "CBO"
*MEAS_COND_AXIS_NAME_INTERNAL-13 "CBO-M"
*MEAS_COND_AXIS_NAME_INTERNAL-14 "IncidentSollerSlit"
*MEAS_COND_AXIS_NAME_INTERNAL-15 "IncidentSlitBox"
*MEAS_COND_AXIS_NAME_INTERNAL-16 "IncidentSlitBox-_Axis"
*MEAS_COND_AXIS_NAME_INTERNAL-17 "Zs"
*MEAS_COND_AXIS_NAME_INTERNAL-18 "IncidentMonochromator"
*MEAS_COND_AXIS_NAME_INTERNAL-19 "IncidentMonochromator-OmegaM"
*MEAS_COND_AXIS_NAME_INTERNAL-20 "IncidentAxdSlit"
*MEAS_COND_AXIS_NAME_INTERNAL-21 "CenterSlit"
*MEAS_COND_AXIS_NAME_INTERNAL-22 "Filter"
*MEAS_COND_AXIS_NAME_INTERNAL-23 "ReceivingSlitBox1"
*MEAS_COND_AXIS_NAME_INTERNAL-24 "ReceivingSlitBox2"
*MEAS_COND_AXIS_NAME_INTERNAL-25 "ReceivingOptics"
*MEAS_COND_AXIS_NAME_INTERNAL-26 "ReceivingSollerSlit"
*MEAS_COND_AXIS_NAME_INTERNAL-27 "ReceivingAxdSlit"
*MEAS_COND_AXIS_NAME_INTERNAL-28 "ReceivingSlitBox1-_Axis"
*MEAS_COND_AXIS_NAME_INTERNAL-29 "ReceivingSlitBox2-_Axis"
*MEAS_COND_AXIS_NAME_INTERNAL-30 "ReceivingSlitBox2-Zd"
*MEAS_COND_AXIS_NAME_INTERNAL-31 "Attenuator"
*MEAS_COND_AXIS_NAME_INTERNAL-32 "CounterMonochromator"
*MEAS_COND_AXIS_NAME_INTERNAL-33 "CounterSlit"
*MEAS_COND_AXIS_NAME_INTERNAL-34 "AlphaR"
*MEAS_COND_AXIS_NAME_INTERNAL-35 "BetaR"
*MEAS_COND_AXIS_NAME_INTERNAL-36 "IncidentPrimary"
*MEAS_COND_AXIS_NAME_INTERNAL-37 "HV"
*MEAS_COND_AXIS_NAME_INTERNAL-38 "PHA"
*MEAS_COND_AXIS_NAME_MAGICNO-0 "83951616.0000000000"
*MEAS_COND_AXIS_NAME_MAGICNO-1 "268632064.0000000000"
*MEAS_COND_AXIS_NAME_MAGICNO-2 "268500992.0000000000"
*MEAS_COND_AXIS_NAME_MAGICNO-3 "268500992.0000000000"
*MEAS_COND_AXIS_NAME_MAGICNO-4 "268500992.0000000000"
*MEAS_COND_AXIS_NAME_MAGICNO-5 "285278208.0000000000"
*MEAS_COND_AXIS_NAME_MAGICNO-6 "268500992.0000000000"
*MEAS_COND_AXIS_NAME_MAGICNO-7 "268500992.0000000000"
*MEAS_COND_AXIS_NAME_MAGICNO-8 "83951616.0000000000"
*MEAS_COND_AXIS_NAME_MAGICNO-9 "131072.0000000000"
*MEAS_COND_AXIS_NAME_MAGICNO-10 "131072.0000000000"
*MEAS_COND_AXIS_NAME_MAGICNO-11 "318898176.0000000000"
*MEAS_COND_AXIS_NAME_MAGICNO-12 "20971521.0000000000"
*MEAS_COND_AXIS_NAME_MAGICNO-13 "285343744.0000000000"
*MEAS_COND_AXIS_NAME_MAGICNO-14 "20971521.0000000000"
*MEAS_COND_AXIS_NAME_MAGICNO-15 "22020097.0000000000"
*MEAS_COND_AXIS_NAME_MAGICNO-16 "25165824.0000000000"
*MEAS_COND_AXIS_NAME_MAGICNO-17 "318898176.0000000000"
*MEAS_COND_AXIS_NAME_MAGICNO-18 "20971521.0000000000"
*MEAS_COND_AXIS_NAME_MAGICNO-19 "285343744.0000000000"
*MEAS_COND_AXIS_NAME_MAGICNO-20 "20971521.0000000000"
*MEAS_COND_AXIS_NAME_MAGICNO-21 "20971521.0000000000"
*MEAS_COND_AXIS_NAME_MAGICNO-22 "20971521.0000000000"
*MEAS_COND_AXIS_NAME_MAGICNO-23 "23068673.0000000000"
*MEAS_COND_AXIS_NAME_MAGICNO-24 "23068673.0000000000"
*MEAS_COND_AXIS_NAME_MAGICNO-25 "20971521.0000000000"
*MEAS_COND_AXIS_NAME_MAGICNO-26 "20971521.0000000000"
*MEAS_COND_AXIS_NAME_MAGICNO-27 "20971521.0000000000"
*MEAS_COND_AXIS_NAME_MAGICNO-28 "25165824.0000000000"
*MEAS_COND_AXIS_NAME_MAGICNO-29 "25165824.0000000000"
*MEAS_COND_AXIS_NAME_MAGICNO-30 "285343744.0000000000"
*MEAS_COND_AXIS_NAME_MAGICNO-31 "17301505.0000000000"
*MEAS_COND_AXIS_NAME_MAGICNO-32 "20971521.0000000000"
*MEAS_COND_AXIS_NAME_MAGICNO-33 "20971521.0000000000"
*MEAS_COND_AXIS_NAME_MAGICNO-34 "8388608.0000000000"
*MEAS_COND_AXIS_NAME_MAGICNO-35 "8388608.0000000000"
*MEAS_COND_AXIS_NAME_MAGICNO-36 "20971521.0000000000"
*MEAS_COND_AXIS_NAME_MAGICNO-37 "0.0000000000"
*MEAS_COND_AXIS_NAME_MAGICNO-38 "0.0000000000"
*MEAS_COND_AXIS_OFFSET-0 "-"
*MEAS_COND_AXIS_OFFSET-1 "0.9861000000"
*MEAS_COND_AXIS_OFFSET-2 "0.9604000000"
*MEAS_COND_AXIS_OFFSET-3 "0.0000000000"
*MEAS_COND_AXIS_OFFSET-4 "0.0000000000"
*MEAS_COND_AXIS_OFFSET-5 "-"
*MEAS_COND_AXIS_OFFSET-6 "-"
*MEAS_COND_AXIS_OFFSET-7 "-"
*MEAS_COND_AXIS_OFFSET-8 "-"
*MEAS_COND_AXIS_OFFSET-9 "0.9604000000"
*MEAS_COND_AXIS_OFFSET-10 "0.0257000000"
*MEAS_COND_AXIS_OFFSET-11 "-"
*MEAS_COND_AXIS_OFFSET-12 "-"
*MEAS_COND_AXIS_OFFSET-13 "-"
*MEAS_COND_AXIS_OFFSET-14 "-"
*MEAS_COND_AXIS_OFFSET-15 "-"
*MEAS_COND_AXIS_OFFSET-16 "-"
*MEAS_COND_AXIS_OFFSET-17 "-"
*MEAS_COND_AXIS_OFFSET-18 "-"
*MEAS_COND_AXIS_OFFSET-19 "-"
*MEAS_COND_AXIS_OFFSET-20 "-"
*MEAS_COND_AXIS_OFFSET-21 "-"
*MEAS_COND_AXIS_OFFSET-22 "-"
*MEAS_COND_AXIS_OFFSET-23 "-"
*MEAS_COND_AXIS_OFFSET-24 "-"
*MEAS_COND_AXIS_OFFSET-25 "-"
*MEAS_COND_AXIS_OFFSET-26 "-"
*MEAS_COND_AXIS_OFFSET-27 "-"
*MEAS_COND_AXIS_OFFSET-28 "-"
*MEAS_COND_AXIS_OFFSET-29 "-"
*MEAS_COND_AXIS_OFFSET-30 "-"
*MEAS_COND_AXIS_OFFSET-31 "-"
*MEAS_COND_AXIS_OFFSET-32 "-"
*MEAS_COND_AXIS_OFFSET-33 "-"
*MEAS_COND_AXIS_OFFSET-34 "0.0000000000"
*MEAS_COND_AXIS_OFFSET-35 "0.0000000000"
*MEAS_COND_AXIS_OFFSET-36 "-"
*MEAS_COND_AXIS_OFFSET-37 "-"
*MEAS_COND_AXIS_OFFSET-38 "-"
*MEAS_COND_AXIS_POSITION-0 "20.9956000000"
*MEAS_COND_AXIS_POSITION-1 "20.9956000000"
*MEAS_COND_AXIS_POSITION-2 "10.7181000000"
*MEAS_COND_AXIS_POSITION-3 "0.0000000000"
*MEAS_COND_AXIS_POSITION-4 "0.0000000000"
*MEAS_COND_AXIS_POSITION-5 "-0.7394000000"
*MEAS_COND_AXIS_POSITION-6 "0.0000000000"
*MEAS_COND_AXIS_POSITION-7 "0.0000000000"
*MEAS_COND_AXIS_POSITION-8 "20.9956000000"
*MEAS_COND_AXIS_POSITION-9 "10.7181000000"
*MEAS_COND_AXIS_POSITION-10 "10.2775000000"
*MEAS_COND_AXIS_POSITION-11 "-5.9371900000"
*MEAS_COND_AXIS_POSITION-12 "PB"
*MEAS_COND_AXIS_POSITION-13 "0.0000000000"
*MEAS_COND_AXIS_POSITION-14 "Soller_slit_open_s"
*MEAS_COND_AXIS_POSITION-15 "0.500mm"
*MEAS_COND_AXIS_POSITION-16 "0.5000000000"
*MEAS_COND_AXIS_POSITION-17 "-1.1812500000"
*MEAS_COND_AXIS_POSITION-18 "Ge(220)x2"
*MEAS_COND_AXIS_POSITION-19 "0.0000000000"
*MEAS_COND_AXIS_POSITION-20 "10.0mm"
*MEAS_COND_AXIS_POSITION-21 "None"
*MEAS_COND_AXIS_POSITION-22 "None"
*MEAS_COND_AXIS_POSITION-23 "0.300mm"
*MEAS_COND_AXIS_POSITION-24 "0.300mm"
*MEAS_COND_AXIS_POSITION-25 "PSA_open"
*MEAS_COND_AXIS_POSITION-26 "Soller_slit_5.0deg"
*MEAS_COND_AXIS_POSITION-27 "None"
*MEAS_COND_AXIS_POSITION-28 "0.3000000000"
*MEAS_COND_AXIS_POSITION-29 "0.3000000000"
*MEAS_COND_AXIS_POSITION-30 "0.1068800000"
*MEAS_COND_AXIS_POSITION-31 "Open"
*MEAS_COND_AXIS_POSITION-32 "None"
*MEAS_COND_AXIS_POSITION-33 "None"
*MEAS_COND_AXIS_POSITION-34 "0.0000000000"
*MEAS_COND_AXIS_POSITION-35 "0.0000000000"
*MEAS_COND_AXIS_POSITION-36 "None"
*MEAS_COND_AXIS_POSITION-37 "640.5000000000"
*MEAS_COND_AXIS_POSITION-38 "518.7500000000"
*MEAS_COND_AXIS_UNIT-0 "deg"
*MEAS_COND_AXIS_UNIT-1 "deg"
*MEAS_COND_AXIS_UNIT-2 "deg"
*MEAS_COND_AXIS_UNIT-3 "deg"
*MEAS_COND_AXIS_UNIT-4 "deg"
*MEAS_COND_AXIS_UNIT-5 "mm"
*MEAS_COND_AXIS_UNIT-6 "mm"
*MEAS_COND_AXIS_UNIT-7 "mm"
*MEAS_COND_AXIS_UNIT-8 "deg"
*MEAS_COND_AXIS_UNIT-9 "deg"
*MEAS_COND_AXIS_UNIT-10 "deg"
*MEAS_COND_AXIS_UNIT-11 "mm"
*MEAS_COND_AXIS_UNIT-12 ""
*MEAS_COND_AXIS_UNIT-13 "pulse"
*MEAS_COND_AXIS_UNIT-14 ""
*MEAS_COND_AXIS_UNIT-15 ""
*MEAS_COND_AXIS_UNIT-16 "mm"
*MEAS_COND_AXIS_UNIT-17 "mm"
*MEAS_COND_AXIS_UNIT-18 ""
*MEAS_COND_AXIS_UNIT-19 "pulse"
*MEAS_COND_AXIS_UNIT-20 ""
*MEAS_COND_AXIS_UNIT-21 ""
*MEAS_COND_AXIS_UNIT-22 ""
*MEAS_COND_AXIS_UNIT-23 ""
*MEAS_COND_AXIS_UNIT-24 ""
*MEAS_COND_AXIS_UNIT-25 ""
*MEAS_COND_AXIS_UNIT-26 ""
*MEAS_COND_AXIS_UNIT-27 ""
*MEAS_COND_AXIS_UNIT-28 "mm"
*MEAS_COND_AXIS_UNIT-29 "mm"
*MEAS_COND_AXIS_UNIT-30 "mm"
*MEAS_COND_AXIS_UNIT-31 ""
*MEAS_COND_AXIS_UNIT-32 ""
*MEAS_COND_AXIS_UNIT-33 ""
*MEAS_COND_AXIS_UNIT-34 "deg"
*MEAS_COND_AXIS_UNIT-35 "deg"
*MEAS_COND_AXIS_UNIT-36 ""
*MEAS_COND_AXIS_UNIT-37 "V"
*MEAS_COND_AXIS_UNIT-38 "mV"
*MEAS_COND_COUNTER_CNTLOSS_CORR "1.0000000000"
*MEAS_COND_COUNTER_PHABASE "518.7500000000"
*MEAS_COND_COUNTER_PHAWINDOW "975.0000000000"
*MEAS_COND_COUNTER_PHA_UNIT "mV"
*MEAS_COND_COUNTER_TAUDIFF "0.2041780000"
*MEAS_COND_COUNTER_TAUINT "0.7545440000"
*MEAS_COND_IRRADIATION_MODE "OFF"
*MEAS_COND_IRRADIATION_WIDTH ""
*MEAS_COND_OPT_ATTR "High resolution parallel beam Ge(220)x2/RS"
*MEAS_COND_OPT_NAME "@High resolution PB-Ge(220)x2"
*MEAS_COND_UNSYMMETRIC_MODE "OFF"
*MEAS_COND_XG_CURRENT "200.0000000000"
*MEAS_COND_XG_VOLTAGE "45.0000000000"
*MEAS_COND_XG_WAVE_TYPE "Ka1"
*MEAS_DATA_COUNT "300.0000000000"
*MEAS_SCAN_AXIS_X "2-Theta/Omega"
*MEAS_SCAN_AXIS_X_INTERNAL "TwoThetaOmega"
*MEAS_SCAN_END_TIME "03/04/16 15:20:05"
*MEAS_SCAN_MODE "CONTINUOUS"
*MEAS_SCAN_MONITOR "0"
*MEAS_SCAN_RESOLUTION_X "0.000200"
*MEAS_SCAN_SPEED "0.200000"
*MEAS_SCAN_SPEED_UNIT "deg/min"
*MEAS_SCAN_START "21.0006000000"
*MEAS_SCAN_START_TIME "03/04/16 15:04:42"
*MEAS_SCAN_STEP "0.0100000000"
*MEAS_SCAN_STOP "23.9906000000"
*MEAS_SCAN_UNIT_X "deg"
*MEAS_SCAN_UNIT_Y "counts"
*RAS_HEADER_END
*RAS_INT_START
21.0006 659.0000 1.0000
21.0106 771.0000 1.0000
21.0206 809.0000 1.0000
21.0306 962.0000 1.0000
21.0406 1192.0000 1.0000
21.0506 1385.0000 1.0000
21.0606 1599.0000 1.0000
21.0706 1788.0000 1.0000
21.0806 2013.0000 1.0000
21.0906 2112.0000 1.0000
21.1006 2174.0000 1.0000
21.1106 2355.0000 1.0000
21.1206 2303.0000 1.0000
21.1306 2334.0000 1.0000
21.1406 2282.0000 1.0000
21.1506 2262.0000 1.0000
21.1606 2084.0000 1.0000
21.1706 1832.0000 1.0000
21.1806 1788.0000 1.0000
21.1906 1638.0000 1.0000
21.2006 1491.0000 1.0000
21.2106 1296.0000 1.0000
21.2206 1135.0000 1.0000
21.2306 1025.0000 1.0000
21.2406 882.0000 1.0000
21.2506 868.0000 1.0000
21.2606 870.0000 1.0000
21.2706 929.0000 1.0000
21.2806 1153.0000 1.0000
21.2906 1325.0000 1.0000
21.3006 1440.0000 1.0000
21.3106 1827.0000 1.0000
21.3206 2161.0000 1.0000
21.3306 2435.0000 1.0000
21.3406 2763.0000 1.0000
21.3506 3165.0000 1.0000
21.3606 3392.0000 1.0000
21.3706 3662.0000 1.0000
21.3806 3860.0000 1.0000
21.3906 4009.0000 1.0000
21.4006 4236.0000 1.0000
21.4106 4143.0000 1.0000
21.4206 4073.0000 1.0000
21.4306 3983.0000 1.0000
21.4406 3731.0000 1.0000
21.4506 3510.0000 1.0000
21.4606 3425.0000 1.0000
21.4706 2993.0000 1.0000
21.4806 2672.0000 1.0000
21.4906 2440.0000 1.0000
21.5006 2086.0000 1.0000
21.5106 1891.0000 1.0000
21.5206 1866.0000 1.0000
21.5306 1734.0000 1.0000
21.5406 1836.0000 1.0000
21.5506 2040.0000 1.0000
21.5606 2295.0000 1.0000
21.5706 2714.0000 1.0000
21.5806 3130.0000 1.0000
21.5906 3666.0000 1.0000
21.6006 4170.0000 1.0000
21.6106 4854.0000 1.0000
21.6206 5482.0000 1.0000
21.6306 6182.0000 1.0000
21.6406 6950.0000 1.0000
21.6506 7521.0000 1.0000
21.6606 7936.0000 1.0000
21.6706 8240.0000 1.0000
21.6806 8699.0000 1.0000
21.6906 8477.0000 1.0000
21.7006 8543.0000 1.0000
21.7106 8464.0000 1.0000
21.7206 8006.0000 1.0000
21.7306 7974.0000 1.0000
21.7406 7306.0000 1.0000
21.7506 6703.0000 1.0000
21.7606 6309.0000 1.0000
21.7706 5607.0000 1.0000
21.7806 5298.0000 1.0000
21.7906 4808.0000 1.0000
21.8006 4843.0000 1.0000
21.8106 4785.0000 1.0000
21.8206 5013.0000 1.0000
21.8306 5393.0000 1.0000
21.8406 6023.0000 1.0000
21.8506 6909.0000 1.0000
21.8606 8220.0000 1.0000
21.8706 9624.0000 1.0000
21.8806 11112.0000 1.0000
21.8906 12647.0000 1.0000
21.9006 14239.0000 1.0000
21.9106 16480.0000 1.0000
21.9206 18180.0000 1.0000
21.9306 19998.0000 1.0000
21.9406 21428.0000 1.0000
21.9506 23165.0000 1.0000
21.9606 24328.0000 1.0000
21.9706 25299.0000 1.0000
21.9806 26008.0000 1.0000
21.9906 26188.0000 1.0000
22.0006 26236.0000 1.0000
22.0106 25975.0000 1.0000
22.0206 25834.0000 1.0000
22.0306 25277.0000 1.0000
22.0406 24856.0000 1.0000
22.0506 24685.0000 1.0000
22.0606 25062.0000 1.0000
22.0706 25470.0000 1.0000
22.0806 27111.0000 1.0000
22.0906 29333.0000 1.0000
22.1006 33100.0000 1.0000
22.1106 38250.0000 1.0000
22.1206 45393.0000 1.0000
22.1306 54472.0000 1.0000
22.1406 67976.0000 1.0000
22.1506 85264.0000 1.0000
22.1606 107265.0000 1.0000
22.1706 138074.0000 1.0000
22.1806 181504.0000 1.0000
22.1906 249964.0000 1.0000
22.2006 389075.0000 1.0000
22.2106 853234.0000 1.0000
22.2206 59799.0039 43.0962
22.2306 137600.0000 43.0962
22.2406 234559.0156 43.0962
22.2506 341022.0000 43.0962
22.2606 437192.9688 43.0962
22.2706 505551.0313 43.0962
22.2806 522854.0000 43.0962
22.2906 469117.0000 43.0962
22.3006 375826.0000 43.0962
22.3106 262764.0000 43.0962
22.3206 160854.0000 43.0962
22.3306 88570.0000 43.0962
22.3406 47156.0000 43.0962
22.3506 22686.0000 43.0962
22.3606 371255.0000 1.0000
22.3706 154015.0000 1.0000
22.3806 104941.0000 1.0000
22.3906 79637.0000 1.0000
22.4006 61882.0000 1.0000
22.4106 50119.0000 1.0000
22.4206 40880.0000 1.0000
22.4306 34456.0000 1.0000
22.4406 29988.0000 1.0000
22.4506 27065.0000 1.0000
22.4606 26114.0000 1.0000
22.4706 26615.0000 1.0000
22.4806 28969.0000 1.0000
22.4906 33195.0000 1.0000
22.5006 39474.0000 1.0000
22.5106 47514.0000 1.0000
22.5206 57019.0000 1.0000
22.5306 67787.0000 1.0000
22.5406 80431.0000 1.0000
22.5506 94022.0000 1.0000
22.5606 109586.0000 1.0000
22.5706 125008.0000 1.0000
22.5806 141711.0000 1.0000
22.5906 156784.0000 1.0000
22.6006 172287.0000 1.0000
22.6106 187029.0000 1.0000
22.6206 201094.0000 1.0000
22.6306 213824.0000 1.0000
22.6406 224644.0000 1.0000
22.6506 234283.0000 1.0000
22.6606 242061.0000 1.0000
22.6706 247788.0000 1.0000
22.6806 250593.0000 1.0000
22.6906 251206.0000 1.0000
22.7006 250025.0000 1.0000
22.7106 246414.0000 1.0000
22.7206 239805.0000 1.0000
22.7306 231824.0000 1.0000
22.7406 221040.0000 1.0000
22.7506 210053.0000 1.0000
22.7606 197104.0000 1.0000
22.7706 184290.0000 1.0000
22.7806 168016.0000 1.0000
22.7906 153654.0000 1.0000
22.8006 137646.0000 1.0000
22.8106 121697.0000 1.0000
22.8206 105831.0000 1.0000
22.8306 91609.0000 1.0000
22.8406 77923.0000 1.0000
22.8506 64564.0000 1.0000
22.8606 52794.0000 1.0000
22.8706 42420.0000 1.0000
22.8806 33056.0000 1.0000
22.8906 24920.0000 1.0000
22.9006 18601.0000 1.0000
22.9106 13059.0000 1.0000
22.9206 8911.0000 1.0000
22.9306 6071.0000 1.0000
22.9406 4162.0000 1.0000
22.9506 3214.0000 1.0000
22.9606 2951.0000 1.0000
22.9706 3529.0000 1.0000
22.9806 4366.0000 1.0000
22.9906 5598.0000 1.0000
23.0006 7185.0000 1.0000
23.0106 8830.0000 1.0000
23.0206 10231.0000 1.0000
23.0306 11673.0000 1.0000
23.0406 12796.0000 1.0000
23.0506 13587.0000 1.0000
23.0606 14132.0000 1.0000
23.0706 14569.0000 1.0000
23.0806 14598.0000 1.0000
23.0906 14114.0000 1.0000
23.1006 13330.0000 1.0000
23.1106 12317.0000 1.0000
23.1206 11385.0000 1.0000
23.1306 10335.0000 1.0000
23.1406 8998.0000 1.0000
23.1506 7872.0000 1.0000
23.1606 6450.0000 1.0000
23.1706 5218.0000 1.0000
23.1806 4059.0000 1.0000
23.1906 3004.0000 1.0000
23.2006 2328.0000 1.0000
23.2106 1688.0000 1.0000
23.2206 1164.0000 1.0000
23.2306 935.0000 1.0000
23.2406 885.0000 1.0000
23.2506 913.0000 1.0000
23.2606 1184.0000 1.0000
23.2706 1511.0000 1.0000
23.2806 1866.0000 1.0000
23.2906 2311.0000 1.0000
23.3006 2778.0000 1.0000
23.3106 3260.0000 1.0000
23.3206 3559.0000 1.0000
23.3306 3948.0000 1.0000
23.3406 4153.0000 1.0000
23.3506 4338.0000 1.0000
23.3606 4447.0000 1.0000
23.3706 4491.0000 1.0000
23.3806 4439.0000 1.0000
23.3906 4180.0000 1.0000
23.4006 3923.0000 1.0000
23.4106 3612.0000 1.0000
23.4206 3179.0000 1.0000
23.4306 2720.0000 1.0000
23.4406 2227.0000 1.0000
23.4506 1919.0000 1.0000
23.4606 1559.0000 1.0000
23.4706 1181.0000 1.0000
23.4806 896.0000 1.0000
23.4906 649.0000 1.0000
23.5006 507.0000 1.0000
23.5106 412.0000 1.0000
23.5206 338.0000 1.0000
23.5306 390.0000 1.0000
23.5406 467.0000 1.0000
23.5506 628.0000 1.0000
23.5606 755.0000 1.0000
23.5706 969.0000 1.0000
23.5806 1141.0000 1.0000
23.5906 1398.0000 1.0000
23.6006 1493.0000 1.0000
23.6106 1729.0000 1.0000
23.6206 1819.0000 1.0000
23.6306 1960.0000 1.0000
23.6406 1941.0000 1.0000
23.6506 1990.0000 1.0000
23.6606 1982.0000 1.0000
23.6706 1882.0000 1.0000
23.6806 1796.0000 1.0000
23.6906 1544.0000 1.0000
23.7006 1360.0000 1.0000
23.7106 1224.0000 1.0000
23.7206 1103.0000 1.0000
23.7306 886.0000 1.0000
23.7406 753.0000 1.0000
23.7506 552.0000 1.0000
23.7606 425.0000 1.0000
23.7706 311.0000 1.0000
23.7806 242.0000 1.0000
23.7906 219.0000 1.0000
23.8006 202.0000 1.0000
23.8106 219.0000 1.0000
23.8206 245.0000 1.0000
23.8306 341.0000 1.0000
23.8406 390.0000 1.0000
23.8506 522.0000 1.0000
23.8606 625.0000 1.0000
23.8706 760.0000 1.0000
23.8806 856.0000 1.0000
23.8906 893.0000 1.0000
23.9006 951.0000 1.0000
23.9106 1065.0000 1.0000
23.9206 1083.0000 1.0000
23.9306 1062.0000 1.0000
23.9406 1056.0000 1.0000
23.9506 1016.0000 1.0000
23.9606 948.0000 1.0000
23.9706 913.0000 1.0000
23.9806 794.0000 1.0000
23.9906 682.0000 1.0000
*RAS_INT_END
*RAS_DATA_END